<?xml version="1.0" ?>

<robot name="samurai">

  <material name="Grey">
    <color rgba="0.2 0.2 0.2 1.0"/>
  </material>
  <material name="Orange">
    <color rgba="1.0 0.423529411765 0.0392156862745 1.0"/>
  </material>
  <material name="Blue">
  <color rgba="0.5 0.7 1.0 1.0"/>      
  </material>
  <material name="Red">
    <color rgba="1 0 0 1.0"/>      
  </material>

  <link name="base_link">
    <inertial>
      <origin rpy="0 0 0" xyz="0 0 0.273"/>
      <mass value="5"/>
      <inertia ixx="0.05" ixy="0" ixz="0" iyy="0.05" iyz="0" izz="0.05"/>
    </inertial>
    <visual>
      <origin rpy="0 0 0" xyz="0 0 0.273"/>
      <geometry>
        <cylinder radius="0.05" length="0.546"/>
      </geometry>
      <material name="Grey"/>
    </visual>
  </link>
  <!-- Joint 1 -->
  <joint name="Joint_1" type="revolute">
    <parent link="base_link"/>
    <child link="Link_1"/>
    <origin rpy="0 0 0" xyz="0 0 0.546"/>
    <axis xyz="0 0 1"/>
  </joint>
    <!-- Link 1 -->
  <link name="Link_1">
    <inertial>
      <origin rpy="0 0 0" xyz="0 0 0.5475"/>
      <mass value="5"/>
      <inertia ixx="0.05" ixy="0" ixz="0" iyy="0.05" iyz="0" izz="0.05"/>
    </inertial>
    <visual>
      <origin rpy="0 0 0" xyz="0 0 0.5475"/>
      <geometry>
        <cylinder radius="0.05" length="1.095"/>
      </geometry>
      <material name="Blue"/>
    </visual>
    <visual>
      <origin rpy="0 0 0" xyz="0 0 0"/>
      <geometry>
        <cylinder radius="0.1" length="0.1"/>
      </geometry>
      <material name="Orange"/>
    </visual>
  </link>
  <!-- Joint 2 -->
  <joint name="Joint_2" type="revolute">
    <parent link="Link_1"/>
    <child link="Link_2"/>
    <origin rpy="0 0 0" xyz="0 0 1.095"/>
    <axis xyz="1 0 0"/>
  </joint>
    <!-- Link 2 -->
  <link name="Link_2">
    <inertial>
      <origin rpy="0 0 0" xyz="0 0 0.805"/>
      <mass value="10"/>
      <inertia ixx="0.1" ixy="0" ixz="0" iyy="0.1" iyz="0" izz="0.1"/>
    </inertial>
    <visual>
      <origin rpy="0 0 0" xyz="0 0 0.805"/>
      <geometry>
        <cylinder radius="0.05" length="1.61"/>
      </geometry>
      <material name="Blue"/>
    </visual>
    <visual>
      <origin rpy="0 1.5708 0" xyz="0 0 0"/>
      <geometry>
        <cylinder radius="0.075" length="0.15"/>
      </geometry>
      <material name="Orange"/>
    </visual>
  </link>
  <!-- Joint 3 -->
  <joint name="Joint_3" type="revolute">
    <parent link="Link_2"/>
    <child link="Link_3"/>
    <origin rpy="0 0 0" xyz="0 0 1.61"/>
    <axis xyz="1 0 0"/>
  </joint>
    <!-- Link 3 -->
  <link name="Link_3">
    <inertial>
      <origin rpy="0 0 0" xyz="0 0 1.14"/>
      <mass value="10"/>
      <inertia ixx="0.1" ixy="0" ixz="0" iyy="0.1" iyz="0" izz="0.1"/>
    </inertial>
    <visual>
      <origin rpy="0 0 0" xyz="0 0 1.14"/>
      <geometry>
        <cylinder radius="0.05" length="2.28"/>
      </geometry>
      <material name="Blue"/>
    </visual>
    <visual>
      <origin rpy="0 1.5708 0" xyz="0 0 0"/>
      <geometry>
        <cylinder radius="0.075" length="0.15"/>
      </geometry>
      <material name="Orange"/>
    </visual>
  </link>
  <!-- Joint End-Effector -->
  <joint name="Joint_EE" type="fixed">
    <parent link="Link_3"/>
    <child link="Link_EE"/>
    <origin rpy="0 0 0" xyz="0 0 2.28"/>
    <axis xyz="1 0 0"/>
  </joint>
    <!-- End-Effector -->
  <link name="Link_EE">
    <inertial>
      <origin rpy="0 0 0" xyz="0 0 0"/>
      <mass value="0"/>
      <inertia ixx="0" ixy="0" ixz="0" iyy="0" iyz="0" izz="0"/>
    </inertial>
    <visual>
      <origin rpy="0 0 0" xyz="0 0 0"/>
      <geometry>
        <sphere radius="0.1"/>
      </geometry>
      <material name="Red"/>
    </visual>
  </link>
  
</robot>